{
  "meta": [
    {
      "key": "support",
      "char": "v"
    },
    {
      "key": "support_points",
      "int_pairs": [
        {
          "x": 5,
          "z": 0
        },
        {
          "x": 5,
          "z": 15
        }
      ]
    }
  ],
  "refpalette": "create_lost_cities:highway",
  "xsize": 16,
  "zsize": 16,
  "slices": [
    [
      "RRRRRvvvvvvvvvvv",
      "RRRRRRRRRRRRRRRR",
      "RRRRRRRRRRRRRRRR",
      "RRRRRRRRRRRRRRRR",
      "RRRRRRRRRRRRRRRR",
      "RRRRRRRRRRRRRRRR",
      "RRRRRRRRRRRRRRRR",
      "uuuuuuuuuuuuuuuu",
      "uuuuuuuuuuuuuuuu",
      "RRRRRRRRRRRRRRRR",
      "RRRRRRRRRRRRRRRR",
      "RRRRRRRRRRRRRRRR",
      "RRRRRRRRRRRRRRRR",
      "RRRRRRRRRRRRRRRR",
      "RRRRRRRRRRRRRRRR",
      "RRRRRvvvvvvvvvvv"
    ],
    [
      ">~~~~vvvvvvvvvvv",
      "]~~~~~~~~~~~~•~~",
      "~~~~~~~~~~~~~~~~",
      "~~~~~~~~~~~~~~~~",
      "||||||||||||||||",
      "~~~~~~~~~~~~~~~~",
      "~~~~~~~~~~~~~~~~",
      "~~~~~~~~~~~~~~~~",
      "~~~~~~~~~~~~~~~~",
      "~~~~~~~~~~~~~~~~",
      "<~~~~~~~~~~~~~~~",
      "||||||||||||||||",
      "~~~~~~~~~~~~~~~~",
      "~~~~~~~~~~~~~~~~",
      "[~~~~~~~~~~~~•~~",
      "~~~~~vvvvvvvvvvv"
    ],
    [
      "~~~~~vvvvvvvvvvv",
      "~~~~~~~~~~~~~•~~",
      "~~~~~~~~~~~~~~~~",
      "~~~~~~~~~~~~~~~~",
      "~~~~~~~~~~~~~~~~",
      "~~~~~~~~~~~~~~~~",
      "~~~~~~~~~~~~~~~~",
      "~~~~~~~~~~~~~~~~",
      "~~~~~~~~~~~~~~~~",
      "~~~~~~~~~~~~~~~~",
      "~~~~~~~~~~~~~~~~",
      "~~~~~~~~~~~~~~~~",
      "~~~~~~~~~~~~~~~~",
      "~~~~~~~~~~~~~~~~",
      "~~~~~~~~~~~~~•~~",
      "~~~~~vvvvvvvvvvv"
    ],
    [
      "~~~~~vvvvvvvvvvv",
      "~~~~~~~~~~~~~•~~",
      "~~~~~~~~~~~~~~~~",
      "~~~~~~~~~~~~~~~~",
      "~~~~~~~~~~~~~~~~",
      "~~~~~~~~~~~~~~~~",
      "~~~~~~~~~~~~~~~~",
      "~~~~~~~~~~~~~~~~",
      "~~~~~~~~~~~~~~~~",
      "~~~~~~~~~~~~~~~~",
      "~~~~~~~~~~~~~~~~",
      "~~~~~~~~~~~~~~~~",
      "~~~~~~~~~~~~~~~~",
      "~~~~~~~~~~~~~~~~",
      "~~~~~~~~~~~~~•~~",
      "~~~~~vvvvvvvvvvv"
    ],
    [
      "~~~~~vvvvvvvvvvv",
      "~~~~~~~~~~~~~•~~",
      "~~~~~~~~~~~~~~~~",
      "~~~~~~~~~~~~~~~~",
      "~~~~~~~~~~~~~~~~",
      "~~~~~~~~~~~~~~~~",
      "~~~~~~~~~~~~~~~~",
      "~~~~~~~~~~~~~~~~",
      "~~~~~~~~~~~~~~~~",
      "~~~~~~~~~~~~~~~~",
      "~~~~~~~~~~~~~~~~",
      "~~~~~~~~~~~~~~~~",
      "~~~~~~~~~~~~~~~~",
      "~~~~~~~~~~~~~~~~",
      "~~~~~~~~~~~~~•~~",
      "~~~~~vvvvvvvvvvv"
    ],
    [
      "~~•~v           ",
      "~~~~~vvvvvvvvvvv",
      "~~~~~~~~~~~~~•~~",
      "~~~~~~~~~~~~~~~~",
      "~~~~~~~~~~~~~~~~",
      "~~~~~~~~~~~~~~~~",
      "~~~~~~~~~~~~~~~~",
      "~~~~~~~~~~~~~~~~",
      "~~~~~~~~~~~~~~~~",
      "~~~~~~~~~~~~~~~~",
      "~~~~~~~~~~~~~~~~",
      "~~~~~~~~~~~~~~~~",
      "~~~~~~~~~~~~~~~~",
      "~~~~~~~~~~~~~•~~",
      "~~~~~vvvvvvvvvvv",
      "~~•~v           "
    ],
    [
      "~~•~v           ",
      "~~~~~vvvvvvvvvvv",
      "~~~~~~~~~~~~~•~~",
      "~~~~~~~~~~~~~~~~",
      "~~~~~~~~~~~~~~~~",
      "~~~~~~~~~~~~~~~~",
      "~~~~~~~~~~~~~~~~",
      "~~~~~~~~~~~~~~~~",
      "~~~~~~~~~~~~~~~~",
      "~~~~~~~~~~~~~~~~",
      "~~~~~~~~~~~~~~~~",
      "~~~~~~~~~~~~~~~~",
      "~~~~~~~~~~~~~~~~",
      "~~~~~~~~~~~~~•~~",
      "~~~~~vvvvvvvvvvv",
      "~~•~v           "
    ],
    [
      "•~•v            ",
      "~•~~v           ",
      "~~~~~vvvvvvvvvvv",
      "~~~~~~~~~~~~~•~~",
      "~~~~~~~~~~~~~•~~",
      "~~~~~~~~~~~~~•~~",
      "~~~~~~~~~~~~~•~~",
      "~~~~~~~~~~~~~i~~",
      "~~~~~~~~~~~~~i~~",
      "~~~~~~~~~~~~~•~~",
      "~~~~~~~~~~~~~•~~",
      "~~~~~~~~~~~~~•~~",
      "~~~~~~~~~~~~~•~~",
      "~~~~~vvvvvvvvvvv",
      "~•~~v           ",
      "•~•v            "
    ],
    [
      "vvv             ",
      "~vvv            ",
      "•~vvv           ",
      "~~vvvvvvvvvvvvvv",
      "~~~vvvvvvvvvvvvv",
      "~~~vvvvvvvvvvvvv",
      "~~~~vvvvvvvvvvvv",
      "~~~~vvvvvvvvvvvv",
      "~~~~vvvvvvvvvvvv",
      "~~~~vvvvvvvvvvvv",
      "~~~vvvvvvvvvvvvv",
      "~~~vvvvvvvvvvvvv",
      "~~vvvvvvvvvvvvvv",
      "•~vvv           ",
      "~vvv            ",
      "vvv             "
    ],
    [
      "                ",
      "v               ",
      "vv              ",
      "vv              ",
      "vvv             ",
      "vvv             ",
      "vvvv            ",
      "vvvv            ",
      "vvvv            ",
      "vvvv            ",
      "vvv             ",
      "vvv             ",
      "vv              ",
      "vv              ",
      "v               ",
      "                "
    ]
  ]
}