{
  "meta": [
    {
      "key": "support",
      "char": "v"
    }
  ],
  "refpalette": "create_lost_cities:highway",
  "xsize": 16,
  "zsize": 16,
  "slices": [
    [
      "RRRRRvvvvvvvvvvv",
      "RRRRRRRRRRRRRRRR",
      "RRRRRRRRRRRRRRRR",
      "RRRRRRRRRRRRRRRR",
      "RRRRRRRRRRRRRRRR",
      "RRRRRRRRRRRRRRRR",
      "RRRRRRRRRRRRRRRR",
      "uuuuuuuuuuuuuuuu",
      "uuuuuuuuuuuuuuuu",
      "RRRRRRRRRRRRRRRR",
      "RRRRRRRRRRRRRRRR",
      "RRRRRRRRRRRRRRRR",
      "RRRRRRRRRRRRRRRR",
      "RRRRRRRRRRRRRRRR",
      "RRRRRRRRRRRRRRRR",
      "RRRRRvvvvvvvvvvv"
    ],
    [
      ">~~~:#::::::::::",
      "]~~~~~~~~~~~~~~~",
      "~~~~~~~~~~~~~~~~",
      "~~~~~~~~~~~~~~~~",
      "||||||||||||||||",
      "~~~~~~~~~~~~~~~~",
      "~~~~~~~~~~~~~~~~",
      "~~~~~~~~~~~~~~~~",
      "~~~~~~~~~~~~~~~~",
      "~~~~~~~~~~~~~~~~",
      "<~~~~~~~~~~~~~~~",
      "||||||||||||||||",
      "~~~~~~~~~~~~~~~~",
      "~~~~~~~~~~~~~~~~",
      "[~~~~~~~~~~~~~~~",
      "~~~~:#::::::::::"
    ],
    [
      "~~~~~q~~~~~~~~~~",
      "~~~~~~~~~~~~~~~~",
      "~~~~~~~~~~~~~~~~",
      "~~~~~~~~~~~~~~~~",
      "~~~~~~~~~~~~~~~~",
      "~~~~~~~~~~~~~~~~",
      "~~~~~~~~~~~~~~~~",
      "~~~~~~~~~~~~~~~~",
      "~~~~~~~~~~~~~~~~",
      "~~~~~~~~~~~~~~~~",
      "~~~~~~~~~~~~~~~~",
      "~~~~~~~~~~~~~~~~",
      "~~~~~~~~~~~~~~~~",
      "~~~~~~~~~~~~~~~~",
      "~~~~~~~~~~~~~~~~",
      "~~~~~q~~~~~~~~~~"
    ],
    [
      "~~~~~q~~~~~~~~~~",
      "~~~~~~~~~~~~~~~~",
      "~~~~~~~~~~~~~~~~",
      "~~~~~~~~~~~~~~~~",
      "~~~~~~~~~~~~~~~~",
      "~~~~~~~~~~~~~~~~",
      "~~~~~~~~~~~~~~~~",
      "~~~~~~~~~~~~~~~~",
      "~~~~~~~~~~~~~~~~",
      "~~~~~~~~~~~~~~~~",
      "~~~~~~~~~~~~~~~~",
      "~~~~~~~~~~~~~~~~",
      "~~~~~~~~~~~~~~~~",
      "~~~~~~~~~~~~~~~~",
      "~~~~~~~~~~~~~~~~",
      "~~~~~q~~~~~~~~~~"
    ],
    [
      "~~~~~q~~~~~~~~~~",
      "~~~~~~~~~~~~~~~~",
      "~~~~~~~~~~~~~~~~",
      "~~~~~~~~~~~~~~~~",
      "~~~~~~~~~~~~~~~~",
      "~~~~~~~~~~~~~~~~",
      "~~~~~~~~~~~~~~~~",
      "~~~~~~~~~~~~~~~~",
      "~~~~~~~~~~~~~~~~",
      "~~~~~~~~~~~~~~~~",
      "~~~~~~~~~~~~~~~~",
      "~~~~~~~~~~~~~~~~",
      "~~~~~~~~~~~~~~~~",
      "~~~~~~~~~~~~~~~~",
      "~~~~~~~~~~~~~~~~",
      "~~~~~q~~~~~~~~~~"
    ],
    [
      "~~~~~q~~~~~~~~~~",
      "~~~~~~~~~~~~~~~~",
      "~~~~~~~~~~~~~~~~",
      "~~~~~~~~~~~~~~~~",
      "~~~~~~~~~~~~~~~~",
      "~~~~~~~~~~~~~~~~",
      "~~~~~~~~~~~~~~~~",
      "~~~~~~~~~~~~~~~~",
      "~~~~~~~~~~~~~~~~",
      "~~~~~~~~~~~~~~~~",
      "~~~~~~~~~~~~~~~~",
      "~~~~~~~~~~~~~~~~",
      "~~~~~~~~~~~~~~~~",
      "~~~~~~~~~~~~~~~~",
      "~~~~~~~~~~~~~~~~",
      "~~~~~q~~~~~~~~~~"
    ],
    [
      "~~~~~q~~~~~~~~~~",
      "~~~~~~~~~~~~~~~~",
      "~~~~~~~~~~~~~~~~",
      "~~~~~~~~~~~~~~~~",
      "~~~~~~~~~~~~~~~~",
      "~~~~~~~~~~~~~~~~",
      "~~~~~~~~~~~~~~~~",
      "~~~~~~~~~~~~~~~~",
      "~~~~~~~~~~~~~~~~",
      "~~~~~~~~~~~~~~~~",
      "~~~~~~~~~~~~~~~~",
      "~~~~~~~~~~~~~~~~",
      "~~~~~~~~~~~~~~~~",
      "~~~~~~~~~~~~~~~~",
      "~~~~~~~~~~~~~~~~",
      "~~~~~q~~~~~~~~~~"
    ],
    [
      "~~~~~q~~~~~~~~~~",
      "~~~~~~~~~~~~~~~~",
      "~~~~~~~~~~~~~~~~",
      "~~~~~~~~~~~~~~~~",
      "~~~~~~~~~~~~~~~~",
      "~~~~~~~~~~~~~~~~",
      "~~~~~~~~~~~~~~~~",
      "~~~~~~~~~~~~~~~~",
      "~~~~~~~~~~~~~~~~",
      "~~~~~~~~~~~~~~~~",
      "~~~~~~~~~~~~~~~~",
      "~~~~~~~~~~~~~~~~",
      "~~~~~~~~~~~~~~~~",
      "~~~~~~~~~~~~~~~~",
      "~~~~~~~~~~~~~~~~",
      "~~~~~q~~~~~~~~~~"
    ],
    [
      "~~~~~r~~~~~~~~~~",
      "~~~~~s~~~~~~~~~~",
      "~~~~~s~~~~~~~~~~",
      "~~~~~s~~~~~~~~~~",
      "~~~~~s~~~~~~~~~~",
      "~~~~~s~~~~~~~~~~",
      "~~~~~s~~~~~~~~~~",
      "~~~~~s~~~~~~~~~~",
      "~~~~~s~~~~~~~~~~",
      "~~~~~s~~~~~~~~~~",
      "~~~~~s~~~~~~~~~~",
      "~~~~~s~~~~~~~~~~",
      "~~~~~s~~~~~~~~~~",
      "~~~~~s~~~~~~~~~~",
      "~~~~~s~~~~~~~~~~",
      "~~~~~r~~~~~~~~~~"
    ]
  ]
}