{
  "meta": [
    {
      "key": "support",
      "char": "v"
    }
  ],
  "refpalette": "create_lost_cities:highway",
  "xsize": 16,
  "zsize": 16,
  "slices": [
    [
      "RRRRRRRuuRRRRRRR",
      "RRRRRRRuuRRRRRRR",
      "RRRRRRRuuRRRRRRR",
      "RRRRRRRuuRRRRRRR",
      "RRRRRRRuuRRRRRRR",
      "RRRRRRRuuRRRRRRR",
      "RRRRRRRuuRRRRRRR",
      "uuuuuuuuuuuuuuuu",
      "uuuuuuuuuuuuuuuu",
      "RRRRRRRuuRRRRRRR",
      "RRRRRRRuuRRRRRRR",
      "RRRRRRRuuRRRRRRR",
      "RRRRRRRuuRRRRRRR",
      "RRRRRRRuuRRRRRRR",
      "RRRRRRRuuRRRRRRR",
      "RRRRRRRuuRRRRRRR"
    ],
    [
      "™~~~≠~~~£~~≠~~~]",
      "~~~~≠~~~~~~≠~~~~",
      "~~~~≠~~~~~~≠~~~~",
      "~~~~≠~~~~~~≠~~~~",
      "||||&||||||&||||",
      "~~~~≠~~~~~~≠~~~~",
      "~~~~≠~~~~~~≠~~~~",
      "~~~~≠~~[]~~≠~~~~",
      "V~~~≠~~]^~~≠~~~~",
      "~~~~≠~~~~~~≠~~~~",
      "~~~~≠~~~~~~≠~~~~",
      "||||&||||||&||||",
      "~~~~≠~~~~~~≠~~~~",
      "~~~~≠~~~~~~≠~~~~",
      "~~~~≠~~~~~~≠~~~~",
      "]~~~≠~~~~~~≠~~~["
    ],
    [
      "~~~~~~~~~~~~~~~~",
      "~~~~~~~~~~~~~~~~",
      "~~~~~~~~~~~~~~~~",
      "~~~~~~~~~~~~~~~~",
      "~~~~~~~~~~~~~~~~",
      "~~~~~~~~~~~~~~~~",
      "~~~~~~~~~~~~~~~~",
      "~~~~~~~~~~~~~~~~",
      "~~~~~~~~~~~~~~~~",
      "~~~~~~~~~~~~~~~~",
      "~~~~~~~~~~~~~~~~",
      "~~~~~~~~~~~~~~~~",
      "~~~~~~~~~~~~~~~~",
      "~~~~~~~~~~~~~~~~",
      "~~~~~~~~~~~~~~~~",
      "~~~~~~~~~~~~~~~~"
    ],
    [
      "~~~~~~~~~~~~~~~~",
      "~~~~~~~~~~~~~~~~",
      "~~~~~~~~~~~~~~~~",
      "~~~~~~~~~~~~~~~~",
      "~~~~~~~~~~~~~~~~",
      "~~~~~~~~~~~~~~~~",
      "~~~~~~~~~~~~~~~~",
      "~~~~~~~~~~~~~~~~",
      "~~~~~~~~~~~~~~~~",
      "~~~~~~~~~~~~~~~~",
      "~~~~~~~~~~~~~~~~",
      "~~~~~~~~~~~~~~~~",
      "~~~~~~~~~~~~~~~~",
      "~~~~~~~~~~~~~~~~",
      "~~~~~~~~~~~~~~~~",
      "~~~~~~~~~~~~~~~~"
    ],
    [
      "~~~~~~~~~~~~~~~~",
      "~~~~~~~~~~~~~~~~",
      "~~~~~~~~~~~~~~~~",
      "~~~~~~~~~~~~~~~~",
      "~~~~~~~~~~~~~~~~",
      "~~~~~~~~~~~~~~~~",
      "~~~~~~~~~~~~~~~~",
      "~~~~~~~~~~~~~~~~",
      "~~~~~~~~~~~~~~~~",
      "~~~~~~~~~~~~~~~~",
      "~~~~~~~~~~~~~~~~",
      "~~~~~~~~~~~~~~~~",
      "~~~~~~~~~~~~~~~~",
      "~~~~~~~~~~~~~~~~",
      "~~~~~~~~~~~~~~~~",
      "~~~~~~~~~~~~~~~~"
    ],
    [
      "~~~~~~~~~~~~~~~~",
      "~~~~~~~~~~~~~~~~",
      "~~~~~~~~~~~~~~~~",
      "~~~~~~~~~~~~~~~~",
      "~~~~~~~~~~~~~~~~",
      "~~~~~~~~~~~~~~~~",
      "~~~~~~~~~~~~~~~~",
      "~~~~~~~~~~~~~~~~",
      "~~~~~~~~~~~~~~~~",
      "~~~~~~~~~~~~~~~~",
      "~~~~~~~~~~~~~~~~",
      "~~~~~~~~~~~~~~~~",
      "~~~~~~~~~~~~~~~~",
      "~~~~~~~~~~~~~~~~",
      "~~~~~~~~~~~~~~~~",
      "~~~~~~~~~~~~~~~~"
    ],
    [
      "~~~~~~~~~~~~~~~~",
      "~~~~~~~~~~~~~~~~",
      "~~~~~~~~~~~~~~~~",
      "~~~~~~~~~~~~~~~~",
      "~~~~~~~~~~~~~~~~",
      "~~~~~~~~~~~~~~~~",
      "~~~~~~~~~~~~~~~~",
      "~~~~~~~~~~~~~~~~",
      "~~~~~~~~~~~~~~~~",
      "~~~~~~~~~~~~~~~~",
      "~~~~~~~~~~~~~~~~",
      "~~~~~~~~~~~~~~~~",
      "~~~~~~~~~~~~~~~~",
      "~~~~~~~~~~~~~~~~",
      "~~~~~~~~~~~~~~~~",
      "~~~~~~~~~~~~~~~~"
    ],
    [
      "~~~~~~~~~~~~~~~~",
      "~~~~~~~~~~~~~~~~",
      "~~~~~~~~~~~~~~~~",
      "~~~~~~~~~~~~~~~~",
      "~~~~~~~~~~~~~~~~",
      "~~~~~~~~~~~~~~~~",
      "~~~~~~~~~~~~~~~~",
      "~~~~~~~~~~~~~~~~",
      "~~~~~~~~~~~~~~~~",
      "~~~~~~~~~~~~~~~~",
      "~~~~~~~~~~~~~~~~",
      "~~~~~~~~~~~~~~~~",
      "~~~~~~~~~~~~~~~~",
      "~~~~~~~~~~~~~~~~",
      "~~~~~~~~~~~~~~~~",
      "~~~~~~~~~~~~~~~~"
    ],
    [
      "i~~•~~~~~~~~•~~i",
      "~~~~•~~~~~~•~~~~",
      "~~~~~~~~~~~~~~~~",
      "•~~~~~~~~~~~~~~•",
      "~•~~~~~~~~~~~~•~",
      "~~~~~~~~~~~~~~~~",
      "~~~~~~~~~~~~~~~~",
      "~~~~~~~~~~~~~~~~",
      "~~~~~~~~~~~~~~~~",
      "~~~~~~~~~~~~~~~~",
      "~~~~~~~~~~~~~~~~",
      "~•~~~~~~~~~~~~•~",
      "•~~~~~~~~~~~~~~•",
      "~~~~~~~~~~~~~~~~",
      "~~~~•~~~~~~•~~~~",
      "i~~•~~~~~~~~•~~i"
    ],
    [
      "vvvvvvvvvvvvvvvv",
      "vvvvvv•ii•vvvvvv",
      "vvvv••~~~~••vvvv",
      "vvv•~~~~~~~~•vvv",
      "vv•~•~~~~~~•~•vv",
      "vv•~~•~~~~•~~•vv",
      "v•~~~~~~~~~~~~•v",
      "vi~~~~~~~~~~~~iv",
      "vi~~~~~~~~~~~~iv",
      "v•~~~~~~~~~~~~•v",
      "vv•~~•~~~~•~~•vv",
      "vv•~•~~~~~~•~•vv",
      "vvv•~~~~~~~~•vvv",
      "vvvv••~~~~••vvvv",
      "vvvvvv•ii•vvvvvv",
      "vvvvvvvvvvvvvvvv"
    ],
    [
      "                ",
      "      vvvv      ",
      "    vvvvvvvv    ",
      "   vvvvvvvvvv   ",
      "  vvvvvvvvvvvv  ",
      "  vvvv~~~~vvvv  ",
      " vvvv~•~~•~vvvv ",
      " vvvv~~••~~vvvv ",
      " vvvv~~••~~vvvv ",
      " vvvv~•~~•~vvvv ",
      "  vvvv~~~~vvvv  ",
      "  vvvvvvvvvvvv  ",
      "   vvvvvvvvvv   ",
      "    vvvvvvvv    ",
      "      vvvv      ",
      "                "
    ],
    [
      "                ",
      "                ",
      "                ",
      "                ",
      "                ",
      "      vvvv      ",
      "     vvvvvv     ",
      "     vvvvvv     ",
      "     vvvvvv     ",
      "     vvvvvv     ",
      "      vvvv      ",
      "                ",
      "                ",
      "                ",
      "                ",
      "                "
    ]
  ]
}