{
  "xsize": 16,
  "zsize": 16,
  "slices": [
    [
      "           vRRRR",
      "            vRRR",
      "             vRR",
      "              vR",
      "               v",
      "                ",
      "                ",
      "                ",
      "                ",
      "                ",
      "                ",
      "                ",
      "                ",
      "                ",
      "                ",
      "                "
    ],
    [
      "    ~~~~~~~::~~~",
      "          ~~::~~",
      "            ~::~",
      "             ~::",
      "              ~:",
      "              ~~",
      "               ~",
      "               ~",
      "               ~",
      "               ~",
      "               ~",
      "               ~",
      "                ",
      "                ",
      "                ",
      "                "
    ],
    [
      "  ~~~~~~~~~~~~~~",
      "     ~~~~~~~~~~~",
      "          ~~~~~~",
      "            ~~~~",
      "             ~~~",
      "             ~~~",
      "              ~~",
      "              ~~",
      "              ~~",
      "              ~~",
      "              ~~",
      "               ~",
      "               ~",
      "               ~",
      "                ",
      "                "
    ],
    [
      "~~~~~~~~~~~~~~~~",
      "  ~~~~~~~~~~~~~~",
      "         ~~~~~~~",
      "           ~~~~~",
      "            ~~~~",
      "             ~~~",
      "             ~~~",
      "              ~~",
      "              ~~",
      "              ~~",
      "              ~~",
      "              ~~",
      "              ~~",
      "              ~~",
      "               ~",
      "               ~"
    ],
    [
      "~~~~~~~~~~~~~~~~",
      " ~~~~~~~~~~~~~~~",
      "      ~~~~~~~~~~",
      "          ~~~~~~",
      "            ~~~~",
      "            ~~~~",
      "             ~~~",
      "             ~~~",
      "             ~~~",
      "             ~~~",
      "              ~~",
      "              ~~",
      "              ~~",
      "              ~~",
      "              ~~",
      "               ~"
    ],
    [
      "~~~~~~~~~~~~~~~~",
      " ~~~~~~~~~~~~~~~",
      "  ~~~~~~~~~~~~~~",
      "        ~~~~~~~~",
      "          ~~~~~~",
      "           ~~~~~",
      "            ~~~~",
      "            ~~~~",
      "             ~~~",
      "             ~~~",
      "             ~~~",
      "             ~~~",
      "             ~~~",
      "             ~~~",
      "              ~~",
      "               ~"
    ],
    [
      "~~~~~~~~~~~~~~~~",
      "  ~~~~~~~~~~~~~~",
      "    ~~~~~~~~~~~~",
      "      ~~~~~~~~~~",
      "         ~~~~~~~",
      "           ~~~~~",
      "           ~~~~~",
      "            ~~~~",
      "            ~~~~",
      "            ~~~~",
      "             ~~~",
      "             ~~~",
      "              ~~",
      "              ~~",
      "               ~",
      "               ~"
    ],
    [
      " ~~~~~~~~~~~~~~~",
      "    ~~~~~~~~~~~~",
      "       ~~~~~~~~~",
      "          ~~~~~~",
      "            ~~~~",
      "            ~~~~",
      "             ~~~",
      "             ~~~",
      "             ~~~",
      "              ~~",
      "              ~~",
      "              ~~",
      "               ~",
      "               ~",
      "               ~",
      "                "
    ],
    [
      "   ~~~~~~~~~~~~~",
      "         ~~~~~~~",
      "             ~~~",
      "              ~~",
      "              ~~",
      "              ~~",
      "              ~~",
      "               ~",
      "               ~",
      "               ~",
      "               ~",
      "               ~",
      "               ~",
      "                ",
      "                ",
      "                "
    ]
  ]
}