{
  "meta": [
    {
      "key": "support",
      "char": "v"
    }
  ],
  "refpalette": "create_lost_cities:highway",
  "xsize": 16,
  "zsize": 16,
  "slices": [
    [
      "vvvvvvvvvvvRRRRR",
      "RRRRRRRRRRRRRRRR",
      "RRRRRRRRRRRRRRRR",
      "RRRRRRRRRRRRRRRR",
      "RRRRRRRRRRRRRRRR",
      "RRRRRRRRRRRRRRRR",
      "RRRRRRRRRRRRRRRR",
      "uuuuuuuuuuuuuuuu",
      "uuuuuuuuuuuuuuuu",
      "RRRRRRRRRRRRRRRR",
      "RRRRRRRRRRRRRRRR",
      "RRRRRRRRRRRRRRRR",
      "RRRRRRRRRRRRRRRR",
      "RRRRRRRRRRRRRRRR",
      "RRRRRRRRRRRRRRRR",
      "vvvvvvvvvvvRRRRR"
    ],
    [
      "vvvvvvvvvvv~~~~~",
      "~~•~~~~~~~~~~~~[",
      "~~~~~~~~~~~~~~~~",
      "~~~~~~~~~~~~~~~~",
      "||||||||||||||||",
      "~~~~~~~~<~~~~~~~",
      "~~~~~~~~~~~~~~~~",
      "~~~~~~~~~~~~~~~~",
      "~~~~~~~~~~~~~~~~",
      "~~~~~~~~~~~~~~~~",
      "~~~~~~~~>~~~~~~~",
      "||||||||||||||||",
      "~~~~~~~~~~~~~~~~",
      "~~~~~~~~~~~~~~~~",
      "~~•~~~~~~~~~~~~]",
      "vvvvvvvvvvv~~~~~"
    ],
    [
      "vvvvvvvvvvv~~~~~",
      "~~•~~~~~~~~~~~~~",
      "~~~~~~~~~~~~~~~~",
      "~~~~~~~~~~~~~~~~",
      "~~~~~~~~~~~~~~~~",
      "~~~~~~~~~~~~~~~~",
      "~~~~~~~~~~~~~~~~",
      "~~~~~~~~~~~~~~~~",
      "~~~~~~~~~~~~~~~~",
      "~~~~~~~~~~~~~~~~",
      "~~~~~~~~~~~~~~~~",
      "~~~~~~~~~~~~~~~~",
      "~~~~~~~~~~~~~~~~",
      "~~~~~~~~~~~~~~~~",
      "~~•~~~~~~~~~~~~~",
      "vvvvvvvvvvv~~~~~"
    ],
    [
      "vvvvvvvvvvv~~~~~",
      "~~•~~~~~~~~~~~~~",
      "~~~~~~~~~~~~~~~~",
      "~~~~~~~~~~~~~~~~",
      "~~~~~~~~~~~~~~~~",
      "~~~~~~~~~~~~~~~~",
      "~~~~~~~~~~~~~~~~",
      "~~~~~~~~~~~~~~~~",
      "~~~~~~~~~~~~~~~~",
      "~~~~~~~~~~~~~~~~",
      "~~~~~~~~~~~~~~~~",
      "~~~~~~~~~~~~~~~~",
      "~~~~~~~~~~~~~~~~",
      "~~~~~~~~~~~~~~~~",
      "~~•~~~~~~~~~~~~~",
      "vvvvvvvvvvv~~~~~"
    ],
    [
      "vvvvvvvvvvv~~~~~",
      "~~•~~~~~~~~~~~~~",
      "~~~~~~~~~~~~~~~~",
      "~~~~~~~~~~~~~~~~",
      "~~~~~~~~~~~~~~~~",
      "~~~~~~~~~~~~~~~~",
      "~~~~~~~~~~~~~~~~",
      "~~~~~~~~~~~~~~~~",
      "~~~~~~~~~~~~~~~~",
      "~~~~~~~~~~~~~~~~",
      "~~~~~~~~~~~~~~~~",
      "~~~~~~~~~~~~~~~~",
      "~~~~~~~~~~~~~~~~",
      "~~~~~~~~~~~~~~~~",
      "~~•~~~~~~~~~~~~~",
      "vvvvvvvvvvv~~~~~"
    ],
    [
      "           v~•~~",
      "vvvvvvvvvvv~~~~~",
      "~~•~~~~~~~~~~~~~",
      "~~~~~~~~~~~~~~~~",
      "~~~~~~~~~~~~~~~~",
      "~~~~~~~~~~~~~~~~",
      "~~~~~~~~~~~~~~~~",
      "~~~~~~~~~~~~~~~~",
      "~~~~~~~~~~~~~~~~",
      "~~~~~~~~~~~~~~~~",
      "~~~~~~~~~~~~~~~~",
      "~~~~~~~~~~~~~~~~",
      "~~~~~~~~~~~~~~~~",
      "~~•~~~~~~~~~~~~~",
      "vvvvvvvvvvv~~~~~",
      "           v~•~~"
    ],
    [
      "           v~•~~",
      "vvvvvvvvvvv~~~~~",
      "~~•~~~~~~~~~~~~~",
      "~~~~~~~~~~~~~~~~",
      "~~~~~~~~~~~~~~~~",
      "~~~~~~~~~~~~~~~~",
      "~~~~~~~~~~~~~~~~",
      "~~~~~~~~~~~~~~~~",
      "~~~~~~~~~~~~~~~~",
      "~~~~~~~~~~~~~~~~",
      "~~~~~~~~~~~~~~~~",
      "~~~~~~~~~~~~~~~~",
      "~~~~~~~~~~~~~~~~",
      "~~•~~~~~~~~~~~~~",
      "vvvvvvvvvvv~~~~~",
      "           v~•~~"
    ],
    [
      "            v•~•",
      "           v~~•~",
      "vvvvvvvvvvv~~~~~",
      "~~•~~~~~~~~~~~~~",
      "~~•~~~~~~~~~~~~~",
      "~~•~~~~~~~~~~~~~",
      "~~•~~~~~~~~~~~~~",
      "~~i~~~~~~~~~~~~~",
      "~~i~~~~~~~~~~~~~",
      "~~•~~~~~~~~~~~~~",
      "~~•~~~~~~~~~~~~~",
      "~~•~~~~~~~~~~~~~",
      "~~•~~~~~~~~~~~~~",
      "vvvvvvvvvvv~~~~~",
      "           v~~•~",
      "            v•~•"
    ],
    [
      "             vvv",
      "            vvv~",
      "           vvv~•",
      "vvvvvvvvvvvvvv~~",
      "vvvvvvvvvvvvv~~~",
      "vvvvvvvvvvvvv~~~",
      "vvvvvvvvvvvv~~~~",
      "vvvvvvvvvvvv~~~~",
      "vvvvvvvvvvvv~~~~",
      "vvvvvvvvvvvv~~~~",
      "vvvvvvvvvvvvv~~~",
      "vvvvvvvvvvvvv~~~",
      "vvvvvvvvvvvvvv~~",
      "           vvv~•",
      "            vvv~",
      "             vvv"
    ],
    [
      "                ",
      "               v",
      "              vv",
      "              vv",
      "             vvv",
      "             vvv",
      "            vvvv",
      "            vvvv",
      "            vvvv",
      "            vvvv",
      "             vvv",
      "             vvv",
      "              vv",
      "              vv",
      "               v",
      "                "
    ]
  ]
}